2018-11-16 14:20:02,070 -- Not Found: /favicon.ico --[Thread-19:115776] [django.request:152] [base:get_response] [WARNING]
2018-11-16 14:47:57,755 -- Not Found: /favicon.ico --[Thread-55:123340] [django.request:152] [base:get_response] [WARNING]
2018-11-16 14:48:44,991 -- Not Found: /favicon.ico --[Thread-73:122476] [django.request:152] [base:get_response] [WARNING]
2018-11-16 15:09:09,345 -- Internal Server Error: /statistics/statistics/ --[Thread-477:127792] [django.request:135] [exception:handle_uncaught_exception] [ERROR]
Traceback (most recent call last):
  File "C:\Users\Administrator\AppData\Local\Programs\Python\Python36\lib\site-packages\django\contrib\sessions\backends\base.py", line 202, in _get_session
    return self._session_cache
AttributeError: 'SessionStore' object has no attribute '_session_cache'

During handling of the above exception, another exception occurred:

Traceback (most recent call last):
  File "C:\Users\Administrator\AppData\Local\Programs\Python\Python36\lib\site-packages\pymysql\connections.py", line 916, in connect
    **kwargs)
  File "C:\Users\Administrator\AppData\Local\Programs\Python\Python36\lib\socket.py", line 722, in create_connection
    raise err
  File "C:\Users\Administrator\AppData\Local\Programs\Python\Python36\lib\socket.py", line 713, in create_connection
    sock.connect(sa)
socket.timeout: timed out

During handling of the above exception, another exception occurred:

Traceback (most recent call last):
  File "C:\Users\Administrator\AppData\Local\Programs\Python\Python36\lib\site-packages\django\db\backends\base\base.py", line 213, in ensure_connection
    self.connect()
  File "C:\Users\Administrator\AppData\Local\Programs\Python\Python36\lib\site-packages\django\db\backends\base\base.py", line 189, in connect
    self.connection = self.get_new_connection(conn_params)
  File "C:\Users\Administrator\AppData\Local\Programs\Python\Python36\lib\site-packages\django\db\backends\mysql\base.py", line 274, in get_new_connection
    conn = Database.connect(**conn_params)
  File "C:\Users\Administrator\AppData\Local\Programs\Python\Python36\lib\site-packages\pymysql\__init__.py", line 90, in Connect
    return Connection(*args, **kwargs)
  File "C:\Users\Administrator\AppData\Local\Programs\Python\Python36\lib\site-packages\pymysql\connections.py", line 706, in __init__
    self.connect()
  File "C:\Users\Administrator\AppData\Local\Programs\Python\Python36\lib\site-packages\pymysql\connections.py", line 963, in connect
    raise exc
pymysql.err.OperationalError: (2003, "Can't connect to MySQL server on '10.9.2.142' (timed out)")

The above exception was the direct cause of the following exception:

Traceback (most recent call last):
  File "C:\Users\Administrator\AppData\Local\Programs\Python\Python36\lib\site-packages\django\core\handlers\exception.py", line 41, in inner
    response = get_response(request)
  File "C:\Users\Administrator\AppData\Local\Programs\Python\Python36\lib\site-packages\django\core\handlers\base.py", line 187, in _get_response
    response = self.process_exception_by_middleware(e, request)
  File "C:\Users\Administrator\AppData\Local\Programs\Python\Python36\lib\site-packages\django\core\handlers\base.py", line 185, in _get_response
    response = wrapped_callback(request, *callback_args, **callback_kwargs)
  File "D:\Web_python\Test_Interface_Web\StatisticsManage\views.py", line 10, in statistics
    return render(request, 'StatisticsPage/statisticsinfo.html')
  File "C:\Users\Administrator\AppData\Local\Programs\Python\Python36\lib\site-packages\django\shortcuts.py", line 30, in render
    content = loader.render_to_string(template_name, context, request, using=using)
  File "C:\Users\Administrator\AppData\Local\Programs\Python\Python36\lib\site-packages\django\template\loader.py", line 68, in render_to_string
    return template.render(context, request)
  File "C:\Users\Administrator\AppData\Local\Programs\Python\Python36\lib\site-packages\django\template\backends\django.py", line 66, in render
    return self.template.render(context)
  File "C:\Users\Administrator\AppData\Local\Programs\Python\Python36\lib\site-packages\django\template\base.py", line 207, in render
    return self._render(context)
  File "C:\Users\Administrator\AppData\Local\Programs\Python\Python36\lib\site-packages\django\template\base.py", line 199, in _render
    return self.nodelist.render(context)
  File "C:\Users\Administrator\AppData\Local\Programs\Python\Python36\lib\site-packages\django\template\base.py", line 990, in render
    bit = node.render_annotated(context)
  File "C:\Users\Administrator\AppData\Local\Programs\Python\Python36\lib\site-packages\django\template\base.py", line 957, in render_annotated
    return self.render(context)
  File "C:\Users\Administrator\AppData\Local\Programs\Python\Python36\lib\site-packages\django\template\loader_tags.py", line 177, in render
    return compiled_parent._render(context)
  File "C:\Users\Administrator\AppData\Local\Programs\Python\Python36\lib\site-packages\django\template\base.py", line 199, in _render
    return self.nodelist.render(context)
  File "C:\Users\Administrator\AppData\Local\Programs\Python\Python36\lib\site-packages\django\template\base.py", line 990, in render
    bit = node.render_annotated(context)
  File "C:\Users\Administrator\AppData\Local\Programs\Python\Python36\lib\site-packages\django\template\base.py", line 957, in render_annotated
    return self.render(context)
  File "C:\Users\Administrator\AppData\Local\Programs\Python\Python36\lib\site-packages\django\template\base.py", line 1040, in render
    output = self.filter_expression.resolve(context)
  File "C:\Users\Administrator\AppData\Local\Programs\Python\Python36\lib\site-packages\django\template\base.py", line 708, in resolve
    obj = self.var.resolve(context)
  File "C:\Users\Administrator\AppData\Local\Programs\Python\Python36\lib\site-packages\django\template\base.py", line 849, in resolve
    value = self._resolve_lookup(context)
  File "C:\Users\Administrator\AppData\Local\Programs\Python\Python36\lib\site-packages\django\template\base.py", line 882, in _resolve_lookup
    current = current[bit]
  File "C:\Users\Administrator\AppData\Local\Programs\Python\Python36\lib\site-packages\django\contrib\sessions\backends\base.py", line 57, in __getitem__
    return self._session[key]
  File "C:\Users\Administrator\AppData\Local\Programs\Python\Python36\lib\site-packages\django\contrib\sessions\backends\base.py", line 207, in _get_session
    self._session_cache = self.load()
  File "C:\Users\Administrator\AppData\Local\Programs\Python\Python36\lib\site-packages\django\contrib\sessions\backends\db.py", line 35, in load
    expire_date__gt=timezone.now()
  File "C:\Users\Administrator\AppData\Local\Programs\Python\Python36\lib\site-packages\django\db\models\manager.py", line 85, in manager_method
    return getattr(self.get_queryset(), name)(*args, **kwargs)
  File "C:\Users\Administrator\AppData\Local\Programs\Python\Python36\lib\site-packages\django\db\models\query.py", line 374, in get
    num = len(clone)
  File "C:\Users\Administrator\AppData\Local\Programs\Python\Python36\lib\site-packages\django\db\models\query.py", line 232, in __len__
    self._fetch_all()
  File "C:\Users\Administrator\AppData\Local\Programs\Python\Python36\lib\site-packages\django\db\models\query.py", line 1118, in _fetch_all
    self._result_cache = list(self._iterable_class(self))
  File "C:\Users\Administrator\AppData\Local\Programs\Python\Python36\lib\site-packages\django\db\models\query.py", line 53, in __iter__
    results = compiler.execute_sql(chunked_fetch=self.chunked_fetch)
  File "C:\Users\Administrator\AppData\Local\Programs\Python\Python36\lib\site-packages\django\db\models\sql\compiler.py", line 871, in execute_sql
    sql, params = self.as_sql()
  File "C:\Users\Administrator\AppData\Local\Programs\Python\Python36\lib\site-packages\django\db\models\sql\compiler.py", line 436, in as_sql
    where, w_params = self.compile(self.where) if self.where is not None else ("", [])
  File "C:\Users\Administrator\AppData\Local\Programs\Python\Python36\lib\site-packages\django\db\models\sql\compiler.py", line 373, in compile
    sql, params = node.as_sql(self, self.connection)
  File "C:\Users\Administrator\AppData\Local\Programs\Python\Python36\lib\site-packages\django\db\models\sql\where.py", line 79, in as_sql
    sql, params = compiler.compile(child)
  File "C:\Users\Administrator\AppData\Local\Programs\Python\Python36\lib\site-packages\django\db\models\sql\compiler.py", line 373, in compile
    sql, params = node.as_sql(self, self.connection)
  File "C:\Users\Administrator\AppData\Local\Programs\Python\Python36\lib\site-packages\django\db\models\lookups.py", line 169, in as_sql
    lhs_sql, params = self.process_lhs(compiler, connection)
  File "C:\Users\Administrator\AppData\Local\Programs\Python\Python36\lib\site-packages\django\db\models\lookups.py", line 162, in process_lhs
    db_type = self.lhs.output_field.db_type(connection=connection)
  File "C:\Users\Administrator\AppData\Local\Programs\Python\Python36\lib\site-packages\django\db\models\fields\__init__.py", line 644, in db_type
    return connection.data_types[self.get_internal_type()] % data
  File "C:\Users\Administrator\AppData\Local\Programs\Python\Python36\lib\site-packages\django\utils\functional.py", line 35, in __get__
    res = instance.__dict__[self.name] = self.func(instance)
  File "C:\Users\Administrator\AppData\Local\Programs\Python\Python36\lib\site-packages\django\db\backends\mysql\base.py", line 174, in data_types
    if self.features.supports_microsecond_precision:
  File "C:\Users\Administrator\AppData\Local\Programs\Python\Python36\lib\site-packages\django\utils\functional.py", line 35, in __get__
    res = instance.__dict__[self.name] = self.func(instance)
  File "C:\Users\Administrator\AppData\Local\Programs\Python\Python36\lib\site-packages\django\db\backends\mysql\features.py", line 53, in supports_microsecond_precision
    return self.connection.mysql_version >= (5, 6, 4) and Database.version_info >= (1, 2, 5)
  File "C:\Users\Administrator\AppData\Local\Programs\Python\Python36\lib\site-packages\django\utils\functional.py", line 35, in __get__
    res = instance.__dict__[self.name] = self.func(instance)
  File "C:\Users\Administrator\AppData\Local\Programs\Python\Python36\lib\site-packages\django\db\backends\mysql\base.py", line 385, in mysql_version
    with self.temporary_connection() as cursor:
  File "C:\Users\Administrator\AppData\Local\Programs\Python\Python36\lib\contextlib.py", line 82, in __enter__
    return next(self.gen)
  File "C:\Users\Administrator\AppData\Local\Programs\Python\Python36\lib\site-packages\django\db\backends\base\base.py", line 591, in temporary_connection
    cursor = self.cursor()
  File "C:\Users\Administrator\AppData\Local\Programs\Python\Python36\lib\site-packages\django\db\backends\base\base.py", line 254, in cursor
    return self._cursor()
  File "C:\Users\Administrator\AppData\Local\Programs\Python\Python36\lib\site-packages\django\db\backends\base\base.py", line 229, in _cursor
    self.ensure_connection()
  File "C:\Users\Administrator\AppData\Local\Programs\Python\Python36\lib\site-packages\django\db\backends\base\base.py", line 213, in ensure_connection
    self.connect()
  File "C:\Users\Administrator\AppData\Local\Programs\Python\Python36\lib\site-packages\django\db\utils.py", line 94, in __exit__
    six.reraise(dj_exc_type, dj_exc_value, traceback)
  File "C:\Users\Administrator\AppData\Local\Programs\Python\Python36\lib\site-packages\django\utils\six.py", line 685, in reraise
    raise value.with_traceback(tb)
  File "C:\Users\Administrator\AppData\Local\Programs\Python\Python36\lib\site-packages\django\db\backends\base\base.py", line 213, in ensure_connection
    self.connect()
  File "C:\Users\Administrator\AppData\Local\Programs\Python\Python36\lib\site-packages\django\db\backends\base\base.py", line 189, in connect
    self.connection = self.get_new_connection(conn_params)
  File "C:\Users\Administrator\AppData\Local\Programs\Python\Python36\lib\site-packages\django\db\backends\mysql\base.py", line 274, in get_new_connection
    conn = Database.connect(**conn_params)
  File "C:\Users\Administrator\AppData\Local\Programs\Python\Python36\lib\site-packages\pymysql\__init__.py", line 90, in Connect
    return Connection(*args, **kwargs)
  File "C:\Users\Administrator\AppData\Local\Programs\Python\Python36\lib\site-packages\pymysql\connections.py", line 706, in __init__
    self.connect()
  File "C:\Users\Administrator\AppData\Local\Programs\Python\Python36\lib\site-packages\pymysql\connections.py", line 963, in connect
    raise exc
django.db.utils.OperationalError: (2003, "Can't connect to MySQL server on '10.9.2.142' (timed out)")
2018-11-16 15:09:24,427 -- Not Found: /favicon.ico --[Thread-479:118852] [django.request:152] [base:get_response] [WARNING]
2018-11-16 15:21:41,007 -- Not Found: /favicon.ico --[Thread-780:128360] [django.request:152] [base:get_response] [WARNING]
2018-11-16 15:21:41,009 -- Not Found: /favicon.ico --[Thread-779:129220] [django.request:152] [base:get_response] [WARNING]
2018-11-16 15:36:09,013 -- Not Found: /favicon.ico --[Thread-1005:130780] [django.request:152] [base:get_response] [WARNING]
2018-11-26 14:33:58,864 -- Internal Server Error: /statistics/statistics/ --[Thread-2:44812] [django.request:135] [exception:handle_uncaught_exception] [ERROR]
Traceback (most recent call last):
  File "C:\Users\Administrator\AppData\Local\Programs\Python\Python36\lib\site-packages\django\core\handlers\exception.py", line 41, in inner
    response = get_response(request)
  File "C:\Users\Administrator\AppData\Local\Programs\Python\Python36\lib\site-packages\django\core\handlers\base.py", line 187, in _get_response
    response = self.process_exception_by_middleware(e, request)
  File "C:\Users\Administrator\AppData\Local\Programs\Python\Python36\lib\site-packages\django\core\handlers\base.py", line 185, in _get_response
    response = wrapped_callback(request, *callback_args, **callback_kwargs)
  File "D:\Web_python\Test_Interface_Web\StatisticsManage\views.py", line 12, in statistics
    usercasetotal=Template_detail.objects.filter(Template_info__pnumber=1,isdelete=0).count()
  File "C:\Users\Administrator\AppData\Local\Programs\Python\Python36\lib\site-packages\django\db\models\manager.py", line 85, in manager_method
    return getattr(self.get_queryset(), name)(*args, **kwargs)
  File "C:\Users\Administrator\AppData\Local\Programs\Python\Python36\lib\site-packages\django\db\models\query.py", line 784, in filter
    return self._filter_or_exclude(False, *args, **kwargs)
  File "C:\Users\Administrator\AppData\Local\Programs\Python\Python36\lib\site-packages\django\db\models\query.py", line 802, in _filter_or_exclude
    clone.query.add_q(Q(*args, **kwargs))
  File "C:\Users\Administrator\AppData\Local\Programs\Python\Python36\lib\site-packages\django\db\models\sql\query.py", line 1250, in add_q
    clause, _ = self._add_q(q_object, self.used_aliases)
  File "C:\Users\Administrator\AppData\Local\Programs\Python\Python36\lib\site-packages\django\db\models\sql\query.py", line 1276, in _add_q
    allow_joins=allow_joins, split_subq=split_subq,
  File "C:\Users\Administrator\AppData\Local\Programs\Python\Python36\lib\site-packages\django\db\models\sql\query.py", line 1154, in build_filter
    lookups, parts, reffed_expression = self.solve_lookup_type(arg)
  File "C:\Users\Administrator\AppData\Local\Programs\Python\Python36\lib\site-packages\django\db\models\sql\query.py", line 1034, in solve_lookup_type
    _, field, _, lookup_parts = self.names_to_path(lookup_splitted, self.get_meta())
  File "C:\Users\Administrator\AppData\Local\Programs\Python\Python36\lib\site-packages\django\db\models\sql\query.py", line 1352, in names_to_path
    "Choices are: %s" % (name, ", ".join(available)))
django.core.exceptions.FieldError: Cannot resolve keyword 'Template_info' into field. Choices are: id, interfaceid, interfaceid_id, isdelete, templateid, templateid_id, usercaseid, usercaseid_id
2018-11-26 14:34:00,263 -- Not Found: /favicon.ico --[Thread-3:30068] [django.request:152] [base:get_response] [WARNING]
2018-11-26 14:34:23,950 -- Internal Server Error: /statistics/statistics/ --[Thread-2:41748] [django.request:135] [exception:handle_uncaught_exception] [ERROR]
Traceback (most recent call last):
  File "C:\Users\Administrator\AppData\Local\Programs\Python\Python36\lib\site-packages\django\core\handlers\exception.py", line 41, in inner
    response = get_response(request)
  File "C:\Users\Administrator\AppData\Local\Programs\Python\Python36\lib\site-packages\django\core\handlers\base.py", line 187, in _get_response
    response = self.process_exception_by_middleware(e, request)
  File "C:\Users\Administrator\AppData\Local\Programs\Python\Python36\lib\site-packages\django\core\handlers\base.py", line 185, in _get_response
    response = wrapped_callback(request, *callback_args, **callback_kwargs)
  File "D:\Web_python\Test_Interface_Web\StatisticsManage\views.py", line 10, in statistics
    interfacetotal=Interface_info.objects.filter(pnumber=1,isdelete=0).count('id')  #按项目ID查询接口总数
TypeError: count() takes 1 positional argument but 2 were given
2018-11-26 14:34:52,374 -- Internal Server Error: /statistics/statistics/ --[Thread-2:16168] [django.request:135] [exception:handle_uncaught_exception] [ERROR]
Traceback (most recent call last):
  File "C:\Users\Administrator\AppData\Local\Programs\Python\Python36\lib\site-packages\django\core\handlers\exception.py", line 41, in inner
    response = get_response(request)
  File "C:\Users\Administrator\AppData\Local\Programs\Python\Python36\lib\site-packages\django\core\handlers\base.py", line 187, in _get_response
    response = self.process_exception_by_middleware(e, request)
  File "C:\Users\Administrator\AppData\Local\Programs\Python\Python36\lib\site-packages\django\core\handlers\base.py", line 185, in _get_response
    response = wrapped_callback(request, *callback_args, **callback_kwargs)
  File "D:\Web_python\Test_Interface_Web\StatisticsManage\views.py", line 10, in statistics
    interfacetotal=Interface_info.objects.filter(pnumber=1,isdelete=0).count('id')  #按项目ID查询接口总数
TypeError: count() takes 1 positional argument but 2 were given
2018-11-26 14:35:04,223 -- Internal Server Error: /statistics/statistics/ --[Thread-2:157612] [django.request:135] [exception:handle_uncaught_exception] [ERROR]
Traceback (most recent call last):
  File "C:\Users\Administrator\AppData\Local\Programs\Python\Python36\lib\site-packages\django\core\handlers\exception.py", line 41, in inner
    response = get_response(request)
  File "C:\Users\Administrator\AppData\Local\Programs\Python\Python36\lib\site-packages\django\core\handlers\base.py", line 187, in _get_response
    response = self.process_exception_by_middleware(e, request)
  File "C:\Users\Administrator\AppData\Local\Programs\Python\Python36\lib\site-packages\django\core\handlers\base.py", line 185, in _get_response
    response = wrapped_callback(request, *callback_args, **callback_kwargs)
  File "D:\Web_python\Test_Interface_Web\StatisticsManage\views.py", line 10, in statistics
    interfacetotal=Interface_info.objects.filter(pnumber=1,isdelete=0).count('id')  #按项目ID查询接口总数
TypeError: count() takes 1 positional argument but 2 were given
2018-11-26 14:35:18,532 -- Internal Server Error: /statistics/statistics/ --[Thread-2:40952] [django.request:135] [exception:handle_uncaught_exception] [ERROR]
Traceback (most recent call last):
  File "C:\Users\Administrator\AppData\Local\Programs\Python\Python36\lib\site-packages\django\core\handlers\exception.py", line 41, in inner
    response = get_response(request)
  File "C:\Users\Administrator\AppData\Local\Programs\Python\Python36\lib\site-packages\django\core\handlers\base.py", line 187, in _get_response
    response = self.process_exception_by_middleware(e, request)
  File "C:\Users\Administrator\AppData\Local\Programs\Python\Python36\lib\site-packages\django\core\handlers\base.py", line 185, in _get_response
    response = wrapped_callback(request, *callback_args, **callback_kwargs)
  File "D:\Web_python\Test_Interface_Web\StatisticsManage\views.py", line 10, in statistics
    interfacetotal=Interface_info.objects.filter(pnumber=1,isdelete=0).count('id')  #按项目ID查询接口总数
TypeError: count() takes 1 positional argument but 2 were given
2018-11-26 14:42:37,472 -- Internal Server Error: /statistics/statistics/ --[Thread-2:46704] [django.request:135] [exception:handle_uncaught_exception] [ERROR]
Traceback (most recent call last):
  File "C:\Users\Administrator\AppData\Local\Programs\Python\Python36\lib\site-packages\django\template\base.py", line 507, in parse
    compile_func = self.tags[command]
KeyError: 'interfacetotal'

During handling of the above exception, another exception occurred:

Traceback (most recent call last):
  File "C:\Users\Administrator\AppData\Local\Programs\Python\Python36\lib\site-packages\django\core\handlers\exception.py", line 41, in inner
    response = get_response(request)
  File "C:\Users\Administrator\AppData\Local\Programs\Python\Python36\lib\site-packages\django\core\handlers\base.py", line 187, in _get_response
    response = self.process_exception_by_middleware(e, request)
  File "C:\Users\Administrator\AppData\Local\Programs\Python\Python36\lib\site-packages\django\core\handlers\base.py", line 185, in _get_response
    response = wrapped_callback(request, *callback_args, **callback_kwargs)
  File "D:\Web_python\Test_Interface_Web\StatisticsManage\views.py", line 12, in statistics
    return render(request, 'StatisticsPage/statisticsinfo.html',{'interfacetotal':interfacetotal,'usercasetotal':usercasetotal})
  File "C:\Users\Administrator\AppData\Local\Programs\Python\Python36\lib\site-packages\django\shortcuts.py", line 30, in render
    content = loader.render_to_string(template_name, context, request, using=using)
  File "C:\Users\Administrator\AppData\Local\Programs\Python\Python36\lib\site-packages\django\template\loader.py", line 67, in render_to_string
    template = get_template(template_name, using=using)
  File "C:\Users\Administrator\AppData\Local\Programs\Python\Python36\lib\site-packages\django\template\loader.py", line 21, in get_template
    return engine.get_template(template_name)
  File "C:\Users\Administrator\AppData\Local\Programs\Python\Python36\lib\site-packages\django\template\backends\django.py", line 39, in get_template
    return Template(self.engine.get_template(template_name), self)
  File "C:\Users\Administrator\AppData\Local\Programs\Python\Python36\lib\site-packages\django\template\engine.py", line 162, in get_template
    template, origin = self.find_template(template_name)
  File "C:\Users\Administrator\AppData\Local\Programs\Python\Python36\lib\site-packages\django\template\engine.py", line 136, in find_template
    name, template_dirs=dirs, skip=skip,
  File "C:\Users\Administrator\AppData\Local\Programs\Python\Python36\lib\site-packages\django\template\loaders\base.py", line 44, in get_template
    contents, origin, origin.template_name, self.engine,
  File "C:\Users\Administrator\AppData\Local\Programs\Python\Python36\lib\site-packages\django\template\base.py", line 191, in __init__
    self.nodelist = self.compile_nodelist()
  File "C:\Users\Administrator\AppData\Local\Programs\Python\Python36\lib\site-packages\django\template\base.py", line 230, in compile_nodelist
    return parser.parse()
  File "C:\Users\Administrator\AppData\Local\Programs\Python\Python36\lib\site-packages\django\template\base.py", line 515, in parse
    raise self.error(token, e)
  File "C:\Users\Administrator\AppData\Local\Programs\Python\Python36\lib\site-packages\django\template\base.py", line 513, in parse
    compiled_result = compile_func(self, token)
  File "C:\Users\Administrator\AppData\Local\Programs\Python\Python36\lib\site-packages\django\template\loader_tags.py", line 312, in do_extends
    nodelist = parser.parse()
  File "C:\Users\Administrator\AppData\Local\Programs\Python\Python36\lib\site-packages\django\template\base.py", line 515, in parse
    raise self.error(token, e)
  File "C:\Users\Administrator\AppData\Local\Programs\Python\Python36\lib\site-packages\django\template\base.py", line 513, in parse
    compiled_result = compile_func(self, token)
  File "C:\Users\Administrator\AppData\Local\Programs\Python\Python36\lib\site-packages\django\template\loader_tags.py", line 255, in do_block
    nodelist = parser.parse(('endblock',))
  File "C:\Users\Administrator\AppData\Local\Programs\Python\Python36\lib\site-packages\django\template\base.py", line 509, in parse
    self.invalid_block_tag(token, command, parse_until)
  File "C:\Users\Administrator\AppData\Local\Programs\Python\Python36\lib\site-packages\django\template\base.py", line 565, in invalid_block_tag
    get_text_list(["'%s'" % p for p in parse_until], 'or'),
django.template.exceptions.TemplateSyntaxError: Invalid block tag on line 15: 'interfacetotal', expected 'endblock'. Did you forget to register or load this tag?
2018-11-26 14:42:38,785 -- Not Found: /favicon.ico --[Thread-3:130868] [django.request:152] [base:get_response] [WARNING]
